---
title: "C6318 | Microsoft Docs"
ms.custom: ""
ms.date: "11/04/2016"
ms.reviewer: ""
ms.suite: ""
ms.technology: 
  - "vs-devops-test"
ms.tgt_pltfrm: ""
ms.topic: "article"
f1_keywords: 
  - "C6318"
helpviewer_keywords: 
  - "C6318"
ms.assetid: 3284a83e-bb8e-461c-adcc-cfc66ceea05e
caps.latest.revision: 13
author: "corob-msft"
ms.author: "corob"
manager: "ghogen"
caps.handback.revision: 13
---
# C6318
[!INCLUDE[vs2017banner](../code-quality/includes/vs2017banner.md)]

avviso C6318: \_\_try\/\_\_except definiti in modo non corretto: utilizzo della costante EXCEPTION\_CONTINUE\_SEARCH o di un'altra costante che restituisce zero nell'espressione di filtro eccezioni.  Il codice nel blocco del gestore eccezioni non viene eseguito  
  
 Questo avviso indica che se si verifica un'eccezione nel blocco protetto di questo gestore eccezioni strutturato, l'eccezione non verrà gestita poiché la costante `EXCECPTION_CONTINUE_SEARCH` viene utilizzata nell'espressione di filtro eccezioni.  
  
 Il codice è equivalente al blocco protetto senza il blocco del gestore eccezioni, in quanto quest'ultimo non viene eseguito.  
  
## Esempio  
 Il codice seguente genera questo avviso:  
  
```  
#include <excpt.h>  
#include <stdio.h>  
  
void f (char *pch)  
{  
  __try   
  {  
    // assignment might fail  
    *pch = 0;  
  }   
  __except (EXCEPTION_CONTINUE_SEARCH) // warning 6318  
  {  
    puts("Exception Occurred");  
  }  
}  
```  
  
 Per risolvere il problema, utilizzare il codice seguente:  
  
```  
#include <excpt.h>  
#include <stdio.h>  
#include <windows.h>  
  
void f (char *pch)  
{  
  __try   
  {  
    // assignment might fail  
    *pch = 0;  
  }   
  __except( (GetExceptionCode() == EXCEPTION_ACCESS_VIOLATION) ?  
                EXCEPTION_EXECUTE_HANDLER : EXCEPTION_CONTINUE_SEARCH )  
  {  
    puts("Access violation");  
  }  
}   
```  
  
## Vedere anche  
 [Istruzione try\-except](/visual-cpp/cpp/try-except-statement)